2021-10-16 15:42:02,795 ERROR: Exception on /admin/hair/patterns [POST] [/home/derek/Development/zara_consulting/apps/comececeme/venv/lib/python3.9/site-packages/flask/app.py:1891]
Traceback (most recent call last):
  File "/home/derek/Development/zara_consulting/apps/comececeme/venv/lib/python3.9/site-packages/sqlalchemy/engine/base.py", line 1276, in _execute_context
    self.dialect.do_execute(
  File "/home/derek/Development/zara_consulting/apps/comececeme/venv/lib/python3.9/site-packages/sqlalchemy/engine/default.py", line 593, in do_execute
    cursor.execute(statement, parameters)
psycopg2.errors.UndefinedTable: invalid reference to FROM-clause entry for table "pattern"
LINE 1: ...ttern (name, display_name, image) VALUES ('Test', pattern.na...
                                                             ^
HINT:  There is an entry for table "pattern", but it cannot be referenced from this part of the query.


The above exception was the direct cause of the following exception:

Traceback (most recent call last):
  File "/home/derek/Development/zara_consulting/apps/comececeme/venv/lib/python3.9/site-packages/flask/app.py", line 2447, in wsgi_app
    response = self.full_dispatch_request()
  File "/home/derek/Development/zara_consulting/apps/comececeme/venv/lib/python3.9/site-packages/flask/app.py", line 1952, in full_dispatch_request
    rv = self.handle_user_exception(e)
  File "/home/derek/Development/zara_consulting/apps/comececeme/venv/lib/python3.9/site-packages/flask/app.py", line 1821, in handle_user_exception
    reraise(exc_type, exc_value, tb)
  File "/home/derek/Development/zara_consulting/apps/comececeme/venv/lib/python3.9/site-packages/flask/_compat.py", line 39, in reraise
    raise value
  File "/home/derek/Development/zara_consulting/apps/comececeme/venv/lib/python3.9/site-packages/flask/app.py", line 1950, in full_dispatch_request
    rv = self.dispatch_request()
  File "/home/derek/Development/zara_consulting/apps/comececeme/venv/lib/python3.9/site-packages/flask/app.py", line 1936, in dispatch_request
    return self.view_functions[rule.endpoint](**req.view_args)
  File "/home/derek/Development/zara_consulting/apps/comececeme/app/blueprints/admin/routes.py", line 337, in hair_patterns
    pattern.create_hair_pattern()
  File "/home/derek/Development/zara_consulting/apps/comececeme/app/models.py", line 239, in create_hair_pattern
    db.session.commit()
  File "/home/derek/Development/zara_consulting/apps/comececeme/venv/lib/python3.9/site-packages/sqlalchemy/orm/scoping.py", line 163, in do
    return getattr(self.registry(), name)(*args, **kwargs)
  File "/home/derek/Development/zara_consulting/apps/comececeme/venv/lib/python3.9/site-packages/sqlalchemy/orm/session.py", line 1042, in commit
    self.transaction.commit()
  File "/home/derek/Development/zara_consulting/apps/comececeme/venv/lib/python3.9/site-packages/sqlalchemy/orm/session.py", line 504, in commit
    self._prepare_impl()
  File "/home/derek/Development/zara_consulting/apps/comececeme/venv/lib/python3.9/site-packages/sqlalchemy/orm/session.py", line 483, in _prepare_impl
    self.session.flush()
  File "/home/derek/Development/zara_consulting/apps/comececeme/venv/lib/python3.9/site-packages/sqlalchemy/orm/session.py", line 2523, in flush
    self._flush(objects)
  File "/home/derek/Development/zara_consulting/apps/comececeme/venv/lib/python3.9/site-packages/sqlalchemy/orm/session.py", line 2664, in _flush
    transaction.rollback(_capture_exception=True)
  File "/home/derek/Development/zara_consulting/apps/comececeme/venv/lib/python3.9/site-packages/sqlalchemy/util/langhelpers.py", line 68, in __exit__
    compat.raise_(
  File "/home/derek/Development/zara_consulting/apps/comececeme/venv/lib/python3.9/site-packages/sqlalchemy/util/compat.py", line 182, in raise_
    raise exception
  File "/home/derek/Development/zara_consulting/apps/comececeme/venv/lib/python3.9/site-packages/sqlalchemy/orm/session.py", line 2624, in _flush
    flush_context.execute()
  File "/home/derek/Development/zara_consulting/apps/comececeme/venv/lib/python3.9/site-packages/sqlalchemy/orm/unitofwork.py", line 422, in execute
    rec.execute(self)
  File "/home/derek/Development/zara_consulting/apps/comececeme/venv/lib/python3.9/site-packages/sqlalchemy/orm/unitofwork.py", line 586, in execute
    persistence.save_obj(
  File "/home/derek/Development/zara_consulting/apps/comececeme/venv/lib/python3.9/site-packages/sqlalchemy/orm/persistence.py", line 239, in save_obj
    _emit_insert_statements(
  File "/home/derek/Development/zara_consulting/apps/comececeme/venv/lib/python3.9/site-packages/sqlalchemy/orm/persistence.py", line 1135, in _emit_insert_statements
    result = cached_connections[connection].execute(
  File "/home/derek/Development/zara_consulting/apps/comececeme/venv/lib/python3.9/site-packages/sqlalchemy/engine/base.py", line 1011, in execute
    return meth(self, multiparams, params)
  File "/home/derek/Development/zara_consulting/apps/comececeme/venv/lib/python3.9/site-packages/sqlalchemy/sql/elements.py", line 298, in _execute_on_connection
    return connection._execute_clauseelement(self, multiparams, params)
  File "/home/derek/Development/zara_consulting/apps/comececeme/venv/lib/python3.9/site-packages/sqlalchemy/engine/base.py", line 1124, in _execute_clauseelement
    ret = self._execute_context(
  File "/home/derek/Development/zara_consulting/apps/comececeme/venv/lib/python3.9/site-packages/sqlalchemy/engine/base.py", line 1316, in _execute_context
    self._handle_dbapi_exception(
  File "/home/derek/Development/zara_consulting/apps/comececeme/venv/lib/python3.9/site-packages/sqlalchemy/engine/base.py", line 1510, in _handle_dbapi_exception
    util.raise_(
  File "/home/derek/Development/zara_consulting/apps/comececeme/venv/lib/python3.9/site-packages/sqlalchemy/util/compat.py", line 182, in raise_
    raise exception
  File "/home/derek/Development/zara_consulting/apps/comececeme/venv/lib/python3.9/site-packages/sqlalchemy/engine/base.py", line 1276, in _execute_context
    self.dialect.do_execute(
  File "/home/derek/Development/zara_consulting/apps/comececeme/venv/lib/python3.9/site-packages/sqlalchemy/engine/default.py", line 593, in do_execute
    cursor.execute(statement, parameters)
sqlalchemy.exc.ProgrammingError: (psycopg2.errors.UndefinedTable) invalid reference to FROM-clause entry for table "pattern"
LINE 1: ...ttern (name, display_name, image) VALUES ('Test', pattern.na...
                                                             ^
HINT:  There is an entry for table "pattern", but it cannot be referenced from this part of the query.

[SQL: INSERT INTO pattern (name, display_name, image) VALUES (%(name)s, pattern.name, %(image)s) RETURNING pattern.id]
[parameters: {'name': 'Test', 'image': 'http://res.cloudinary.com/comececeme/image/upload/v1634416921/glqxeefbihyytp5adku3.jpg'}]
(Background on this error at: http://sqlalche.me/e/13/f405)
